[2023-12-10T16:39:31.664+0000] {taskinstance.py:1157} INFO - Dependencies all met for dep_context=non-requeueable deps ti=<TaskInstance: project.missing_value manual__2023-12-10T16:37:07.189289+00:00 [queued]>
[2023-12-10T16:39:31.669+0000] {taskinstance.py:1157} INFO - Dependencies all met for dep_context=requeueable deps ti=<TaskInstance: project.missing_value manual__2023-12-10T16:37:07.189289+00:00 [queued]>
[2023-12-10T16:39:31.669+0000] {taskinstance.py:1359} INFO - Starting attempt 4 of 4
[2023-12-10T16:39:31.676+0000] {taskinstance.py:1380} INFO - Executing <Task(PythonOperator): missing_value> on 2023-12-10 16:37:07.189289+00:00
[2023-12-10T16:39:31.680+0000] {standard_task_runner.py:57} INFO - Started process 521 to run task
[2023-12-10T16:39:31.684+0000] {standard_task_runner.py:84} INFO - Running: ['***', 'tasks', 'run', 'project', 'missing_value', 'manual__2023-12-10T16:37:07.189289+00:00', '--job-id', '10', '--raw', '--subdir', 'DAGS_FOLDER/etl_dag.py', '--cfg-path', '/tmp/tmp4zil3lp8']
[2023-12-10T16:39:31.687+0000] {standard_task_runner.py:85} INFO - Job 10: Subtask missing_value
[2023-12-10T16:39:31.729+0000] {task_command.py:415} INFO - Running <TaskInstance: project.missing_value manual__2023-12-10T16:37:07.189289+00:00 [running]> on host 3e7bdbe00a58
[2023-12-10T16:39:31.786+0000] {taskinstance.py:1660} INFO - Exporting env vars: AIRFLOW_CTX_DAG_EMAIL='sourabhmehta06@gmail.com' AIRFLOW_CTX_DAG_OWNER='sourabh' AIRFLOW_CTX_DAG_ID='project' AIRFLOW_CTX_TASK_ID='missing_value' AIRFLOW_CTX_EXECUTION_DATE='2023-12-10T16:37:07.189289+00:00' AIRFLOW_CTX_TRY_NUMBER='4' AIRFLOW_CTX_DAG_RUN_ID='manual__2023-12-10T16:37:07.189289+00:00'
[2023-12-10T16:39:31.790+0000] {taskinstance.py:1935} ERROR - Task failed with exception
Traceback (most recent call last):
  File "/home/airflow/.local/lib/python3.8/site-packages/airflow/operators/python.py", line 192, in execute
    return_value = self.execute_callable()
  File "/home/airflow/.local/lib/python3.8/site-packages/airflow/operators/python.py", line 209, in execute_callable
    return self.python_callable(*self.op_args, **self.op_kwargs)
  File "/opt/airflow/dags/etl_dag.py", line 36, in missing_value
    df = pd.read_csv(path)
  File "/home/airflow/.local/lib/python3.8/site-packages/pandas/io/parsers/readers.py", line 912, in read_csv
    return _read(filepath_or_buffer, kwds)
  File "/home/airflow/.local/lib/python3.8/site-packages/pandas/io/parsers/readers.py", line 577, in _read
    parser = TextFileReader(filepath_or_buffer, **kwds)
  File "/home/airflow/.local/lib/python3.8/site-packages/pandas/io/parsers/readers.py", line 1407, in __init__
    self._engine = self._make_engine(f, self.engine)
  File "/home/airflow/.local/lib/python3.8/site-packages/pandas/io/parsers/readers.py", line 1661, in _make_engine
    self.handles = get_handle(
  File "/home/airflow/.local/lib/python3.8/site-packages/pandas/io/common.py", line 859, in get_handle
    handle = open(
FileNotFoundError: [Errno 2] No such file or directory: '/opt/airflow/../data/beer_profile_and_ratings.csv'
[2023-12-10T16:39:31.940+0000] {taskinstance.py:1398} INFO - Marking task as FAILED. dag_id=project, task_id=missing_value, execution_date=20231210T163707, start_date=20231210T163931, end_date=20231210T163931
[2023-12-10T16:39:31.948+0000] {standard_task_runner.py:104} ERROR - Failed to execute job 10 for task missing_value ([Errno 2] No such file or directory: '/opt/airflow/../data/beer_profile_and_ratings.csv'; 521)
[2023-12-10T16:39:31.983+0000] {local_task_job_runner.py:228} INFO - Task exited with return code 1
[2023-12-10T16:39:31.998+0000] {taskinstance.py:2776} INFO - 0 downstream tasks scheduled from follow-on schedule check
